/**
 * Generated by Agitar build: JUnitFactory Version 2.1.0.000576 (Build date: Oct 19, 2007) [2.1.0.000576]
 * JDK Version: 1.5.0_11
 *
 * Generated on Nov 8, 2007 7:23:11 PM
 * Time to generate: 00:14.741 seconds
 *
 */

package org.mentawai.core;

import com.agitar.lib.junit.AgitarTestCase;

public class ConsequenceExceptionAgitarTest extends AgitarTestCase {
    
    public Class getTargetClass()  {
        return ConsequenceException.class;
    }
    
    public void testConstructor() throws Throwable {
        Exception e = new ArrayStoreException();
        e.initCause(null);
        ConsequenceException consequenceException = new ConsequenceException(e);
        assertSame("consequenceException.getCause()", e, consequenceException.getCause());
        assertEquals("consequenceException.getMessage()", "java.lang.ArrayStoreException", consequenceException.getMessage());
        // dependencies on static and environment state led to removal of 1 assertion
    }
    
    public void testConstructor1() throws Throwable {
        new ConsequenceException();
        assertTrue("Test call resulted in expected outcome", true);
    }
    
    public void testConstructor2() throws Throwable {
        ConsequenceException consequenceException = new ConsequenceException("testConsequenceExceptionMsg");
        assertEquals("consequenceException.getMessage()", "testConsequenceExceptionMsg", consequenceException.getMessage());
    }
    
    public void testConstructor3() throws Throwable {
        Exception e = new NullPointerException();
        ConsequenceException consequenceException = new ConsequenceException("testConsequenceExceptionMsg", e);
        assertSame("consequenceException.getCause()", e, consequenceException.getCause());
        assertEquals("consequenceException.getMessage()", "testConsequenceExceptionMsg", consequenceException.getMessage());
    }
    
    public void testConstructorThrowsNullPointerException() throws Throwable {
        try {
            new ConsequenceException((Exception) null);
            fail("Expected NullPointerException to be thrown");
        } catch (NullPointerException ex) {
            assertNull("ex.getMessage()", ex.getMessage());
            assertThrownBy(ConsequenceException.class, ex);
        }
    }
}

